Workbook

Sheet README
A1: E-COMMERCE SALES ANALYTICS — EXCEL
B3: Objective | C3: Analyze 2024 e-commerce sales performance across regions, categories and time.
B5: Dataset | C5: 260 cleaned order records after data-quality handling
C6: (255 dated + 5 valid orders retained with an undated assumption — see Cleaning_Log).
B8: Tools | C8: Microsoft Excel — formulas (SUMIFS/COUNTIFS/INDEX-MATCH), data cleaning, formula-driven summaries, data visualization.
B10: Key | C10: Sales, Profit, Profit Margin, AOV, regional performance, category performance, monthly trends, quarterly performance.
B12: Data | C12: Duplicates handled, missing values handled, conflicting OrderIDs
C13: documented (Exceptions_Log), missing-date records retained but excluded from time-based analysis.
B15: Workbook | C15: Dashboard — headline KPIs, top performers, and 4 charts
C16: Analysis — formula-driven region / category / monthly / quarterly summaries
C17: Cleaned_Data — deduplicated, enriched order-level data (260 rows)
C18: Raw_Data — unprocessed export (duplicates + missing values present)
C19: Cleaning_Log — every cleaning step and the assumption behind it
C20: Exceptions_Log — conflicting duplicate OrderIDs and how they were resolved
C21: Customers, Products — lookup/reference tables

Sheet Dashboard
B1: E-COMMERCE SALES DASHBOARD
B3: Calendar Year 2024 | 260 unique orders | Source: Cleaned_Data
B5: TOTAL SALES | E5: TOTAL PROFIT | H5: TOTAL ORDERS | K5: AVG ORDER VALUE | P5: PROFIT MARGIN
B6: =Analysis!A5 -> 1938477.7 | E6: =Analysis!C5 -> 400069.4 | H6: =Analysis!E5 -> 260 | K6: =Analysis!A7 -> 7455.6834 | P6: =Analysis!C7 -> 0.20638329
B9: Top Region: | D9: =Analysis!B49 -> North | F9: Top Category: | H9: =Analysis!B50 -> Beauty | K9: Top Month: | M9: =Analysis!B51 -> Oct

Sheet Cleaned_Data
A1: CLEANED & ENRICHED ORDER DATA
A2: OrderID | B2: CustomerID | C2: CustomerName | D2: Region | E2: ProductID | F2: ProductName | G2: Category | H2: OrderDate | I2: Month | J2: MonthName | K2: Quarter | L2: Quantity | M2: UnitPrice | N2: Discount | O2: CostPrice | P2: Sales | Q2: Profit | R2: Profit Margin % | S2: Order Type | T2: Profit Tier
A3: ORD1044 | B3: CUST009 | C3: =IFERROR(INDEX(Customers!$B$2:$B$31,MATCH(B3,Customers!$A$2:$A$31,0)),"Unknown") -> Aisha Malhotra | D3: =IFERROR(INDEX(Customers!$D$2:$D$31,MATCH(B3,Customers!$A$2:$A$31,0)),"Unknown") -> Central | E3: PROD002 | F3: =IFERROR(INDEX(Products!$B$2:$B$31,MATCH(E3,Products!$A$2:$A$31,0)),"Unknown") -> Bluetooth Speaker | G3: =IFERROR(INDEX(Products!$C$2:$C$31,MATCH(E3,Products!$A$2:$A$31,0)),"Unknown") -> Electronics | H3: 45293 | I3: =IF(H3="","",MONTH(H3)) -> 1 | J3: =IF(H3="","",TEXT(H3,"mmm")) -> Jan | K3: =IF(H3="","","Q"&ROUNDUP(MONTH(H3)/3,0)) -> Q1 | L3: 6 | M3: 3267.99 | N3: 0.15 | O3: =IFERROR(INDEX(Products!$D$2:$D$31,MATCH(E3,Products!$A$2:$A$31,0)),0) -> 2293.21 | P3: =ROUND(L3*M3*(1-N3),2) -> 16666.75 | Q3: =ROUND(P3-L3*O3,2) -> 2907.49 | R3: =IFERROR(Q3/P3,0) -> 0.17444853 | S3: =IF(L3>=5,"Bulk","Regular") -> Bulk | T3: =IF(R3>=0.3,"High",IF(R3>=0.15,"Medium","Low")) -> Medium
A4: ORD1035 | B4: CUST030 | C4: =IFERROR(INDEX(Customers!$B$2:$B$31,MATCH(B4,Customers!$A$2:$A$31,0)),"Unknown") -> Mohammed Patel | D4: =IFERROR(INDEX(Customers!$D$2:$D$31,MATCH(B4,Customers!$A$2:$A$31,0)),"Unknown") -> East | E4: PROD003 | F4: =IFERROR(INDEX(Products!$B$2:$B$31,MATCH(E4,Products!$A$2:$A$31,0)),"Unknown") -> Smartwatch | G4: =IFERROR(INDEX(Products!$C$2:$C$31,MATCH(E4,Products!$A$2:$A$31,0)),"Unknown") -> Electronics | H4: 45296 | I4: =IF(H4="","",MONTH(H4)) -> 1 | J4: =IF(H4="","",TEXT(H4,"mmm")) -> Jan | K4: =IF(H4="","","Q"&ROUNDUP(MONTH(H4)/3,0)) -> Q1 | L4: 8 | M4: 1701.73 | N4: 0.1 | O4: =IFERROR(INDEX(Products!$D$2:$D$31,MATCH(E4,Products!$A$2:$A$31,0)),0) -> 1190.42 | P4: =ROUND(L4*M4*(1-N4),2) -> 12252.46 | Q4: =ROUND(P4-L4*O4,2) -> 2729.1 | R4: =IFERROR(Q4/P4,0) -> 0.22273894 | S4: =IF(L4>=5,"Bulk","Regular") -> Bulk | T4: =IF(R4>=0.3,"High",IF(R4>=0.15,"Medium","Low")) -> Medium
A5: ORD1039 | B5: CUST021 | C5: =IFERROR(INDEX(Customers!$B$2:$B$31,MATCH(B5,Customers!$A$2:$A$31,0)),"Unknown") -> Diya Reddy | D5: =IFERROR(INDEX(Customers!$D$2:$D$31,MATCH(B5,Customers!$A$2:$A$31,0)),"Unknown") -> East | E5: PROD017 | F5: =IFERROR(INDEX(Products!$B$2:$B$31,MATCH(E5,Products!$A$2:$A$31,0)),"Unknown") -> Self-Help Book | G5: =IFERROR(INDEX(Products!$C$2:$C$31,MATCH(E5,Products!$A$2:$A$31,0)),"Unknown") -> Books | H5: 45296 | I5: =IF(H5="","",MONTH(H5)) -> 1 | J5: =IF(H5="","",TEXT(H5,"mmm")) -> Jan | K5: =IF(H5="","","Q"&ROUNDUP(MONTH(H5)/3,0)) -> Q1 | L5: 2 | M5: 2508.38 | N5: 0 | O5: =IFERROR(INDEX(Products!$D$2:$D$31,MATCH(E5,Products!$A$2:$A$31,0)),0) -> 1598.42 | P5: =ROUND(L5*M5*(1-N5),2) -> 5016.76 | Q5: =ROUND(P5-L5*O5,2) -> 1819.92 | R5: =IFERROR(Q5/P5,0) -> 0.362768 | S5: =IF(L5>=5,"Bulk","Regular") -> Regular | T5: =IF(R5>=0.3,"High",IF(R5>=0.15,"Medium","Low")) -> High
A6: ORD1124 | B6: CUST016 | C6: =IFERROR(INDEX(Customers!$B$2:$B$31,MATCH(B6,Customers!$A$2:$A$31,0)),"Unknown") -> Ira Singh | D6: =IFERROR(INDEX(Customers!$D$2:$D$31,MATCH(B6,Customers!$A$2:$A$31,0)),"Unknown") -> West | E6: PROD004 | F6: =IFERROR(INDEX(Products!$B$2:$B$31,MATCH(E6,Products!$A$2:$A$31,0)),"Unknown") -> Power Bank | G6: =IFERROR(INDEX(Products!$C$2:$C$31,MATCH(E6,Products!$A$2:$A$31,0)),"Unknown") -> Electronics | H6: 45298 | I6: =IF(H6="","",MONTH(H6)) -> 1 | J6: =IF(H6="","",TEXT(H6,"mmm")) -> Jan | K6: =IF(H6="","","Q"&ROUNDUP(MONTH(H6)/3,0)) -> Q1 | L6: 5 | M6: 981.46 | N6: 0.05 | O6: =IFERROR(INDEX(Products!$D$2:$D$31,MATCH(E6,Products!$A$2:$A$31,0)),0) -> 721.01 | P6: =ROUND(L6*M6*(1-N6),2) -> 4661.94 | Q6: =ROUND(P6-L6*O6,2) -> 1056.89 | R6: =IFERROR(Q6/P6,0) -> 0.22670605 | S6: =IF(L6>=5,"Bulk","Regular") -> Bulk | T6: =IF(R6>=0.3,"High",IF(R6>=0.15,"Medium","Low")) -> Medium
A7: ORD1213 | B7: CUST001 | C7: =IFERROR(INDEX(Customers!$B$2:$B$31,MATCH(B7,Customers!$A$2:$A$31,0)),"Unknown") -> Sana Singh | D7: =IFERROR(INDEX(Customers!$D$2:$D$31,MATCH(B7,Customers!$A$2:$A$31,0)),"Unknown") -> North | E7: PROD005 | F7: =IFERROR(INDEX(Products!$B$2:$B$31,MATCH(E7,Products!$A$2:$A$31,0)),"Unknown") -> USB-C Cable | G7: =IFERROR(INDEX(Products!$C$2:$C$31,MATCH(E7,Products!$A$2:$A$31,0)),"Unknown") -> Electronics | H7: 45299 | I7: =IF(H7="","",MONTH(H7)) -> 1 | J7: =IF(H7="","",TEXT(H7,"mmm")) -> Jan | K7: =IF(H7="","","Q"&ROUNDUP(MONTH(H7)/3,0)) -> Q1 | L7: 6 | M7: 1018.98 | N7: 0 | O7: =IFERROR(INDEX(Products!$D$2:$D$31,MATCH(E7,Products!$A$2:$A$31,0)),0) -> 676.84 | P7: =ROUND(L7*M7*(1-N7),2) -> 6113.88 | Q7: =ROUND(P7-L7*O7,2) -> 2052.84 | R7: =IFERROR(Q7/P7,0) -> 0.33576714 | S7: =IF(L7>=5,"Bulk","Regular") -> Bulk | T7: =IF(R7>=0.3,"High",IF(R7>=0.15,"Medium","Low")) -> High
A8: ORD1214 | B8: CUST019 | C8: =IFERROR(INDEX(Customers!$B$2:$B$31,MATCH(B8,Customers!$A$2:$A$31,0)),"Unknown") -> Neha Khan | D8: =IFERROR(INDEX(Customers!$D$2:$D$31,MATCH(B8,Customers!$A$2:$A$31,0)),"Unknown") -> East | E8: PROD011 | F8: =IFERROR(INDEX(Products!$B$2:$B$31,MATCH(E8,Products!$A$2:$A$31,0)),"Unknown") -> Non-Stick Pan | G8: =IFERROR(INDEX(Products!$C$2:$C$31,MATCH(E8,Products!$A$2:$A$31,0)),"Unknown") -> Home & Kitchen | H8: 45300 | I8: =IF(H8="","",MONTH(H8)) -> 1 | J8: =IF(H8="","",TEXT(H8,"mmm")) -> Jan | K8: =IF(H8="","","Q"&ROUNDUP(MONTH(H8)/3,0)) -> Q1 | L8: 3 | M8: 775.31 | N8: 0 | O8: =IFERROR(INDEX(Products!$D$2:$D$31,MATCH(E8,Products!$A$2:$A$31,0)),0) -> 610.76 | P8: =ROUND(L8*M8*(1-N8),2) -> 2325.93 | Q8: =ROUND(P8-L8*O8,2) -> 493.65 | R8: =IFERROR(Q8/P8,0) -> 0.21223769 | S8: =IF(L8>=5,"Bulk","Regular") -> Regular | T8: =IF(R8>=0.3,"High",IF(R8>=0.15,"Medium","Low")) -> Medium
A9: ORD1096 | B9: CUST007 | C9: =IFERROR(INDEX(Customers!$B$2:$B$31,MATCH(B9,Customers!$A$2:$A$31,0)),"Unknown") -> Imran Mehta | D9: =IFERROR(INDEX(Customers!$D$2:$D$31,MATCH(B9,Customers!$A$2:$A$31,0)),"Unknown") -> Central | E9: PROD027 | F9: =IFERROR(INDEX(Products!$B$2:$B$31,MATCH(E9,Products!$A$2:$A$31,0)),"Unknown") -> Cricket Bat | G9: =IFERROR(INDEX(Products!$C$2:$C$31,MATCH(E9,Products!$A$2:$A$31,0)),"Unknown") -> Sports | H9: 45302 | I9: =IF(H9="","",MONTH(H9)) -> 1 | J9: =IF(H9="","",TEXT(H9,"mmm")) -> Jan | K9: =IF(H9="","","Q"&ROUNDUP(MONTH(H9)/3,0)) -> Q1 | L9: 3 | M9: 2293.59 | N9: 0.05 | O9: =IFERROR(INDEX(Products!$D$2:$D$31,MATCH(E9,Products!$A$2:$A$31,0)),0) -> 1824.15 | P9: =ROUND(L9*M9*(1-N9),2) -> 6536.73 | Q9: =ROUND(P9-L9*O9,2) -> 1064.28 | R9: =IFERROR(Q9/P9,0) -> 0.16281535 | S9: =IF(L9>=5,"Bulk","Regular") -> Regular | T9: =IF(R9>=0.3,"High",IF(R9>=0.15,"Medium","Low")) -> Medium
A10: ORD1208 | B10: CUST021 | C10: =IFERROR(INDEX(Customers!$B$2:$B$31,MATCH(B10,Customers!$A$2:$A$31,0)),"Unknown") -> Diya Reddy | D10: =IFERROR(INDEX(Customers!$D$2:$D$31,MATCH(B10,Customers!$A$2:$A$31,0)),"Unknown") -> East | E10: PROD020 | F10: =IFERROR(INDEX(Products!$B$2:$B$31,MATCH(E10,Products!$A$2:$A$31,0)),"Unknown") -> Notebook Set | G10: =IFERROR(INDEX(Products!$C$2:$C$31,MATCH(E10,Products!$A$2:$A$31,0)),"Unknown") -> Books | H10: 45302 | I10: =IF(H10="","",MONTH(H10)) -> 1 | J10: =IF(H10="","",TEXT(H10,"mmm")) -> Jan | K10: =IF(H10="","","Q"&ROUNDUP(MONTH(H10)/3,0)) -> Q1 | L10: 1 | M10: 351.56 | N10: 0 | O10: =IFERROR(INDEX(Products!$D$2:$D$31,MATCH(E10,Products!$A$2:$A$31,0)),0) -> 233.74 | P10: =ROUND(L10*M10*(1-N10),2) -> 351.56 | Q10: =ROUND(P10-L10*O10,2) -> 117.82 | R10: =IFERROR(Q10/P10,0) -> 0.33513483 | S10: =IF(L10>=5,"Bulk","Regular") -> Regular | T10: =IF(R10>=0.3,"High",IF(R10>=0.15,"Medium","Low")) -> High
A11: ORD1088 | B11: CUST014 | C11: =IFERROR(INDEX(Customers!$B$2:$B$31,MATCH(B11,Customers!$A$2:$A$31,0)),"Unknown") -> Aisha Sharma | D11: =IFERROR(INDEX(Customers!$D$2:$D$31,MATCH(B11,Customers!$A$2:$A$31,0)),"Unknown") -> Central | E11: PROD016 | F11: =IFERROR(INDEX(Products!$B$2:$B$31,MATCH(E11,Products!$A$2:$A$31,0)),"Unknown") -> Fiction Novel | G11: =IFERROR(INDEX(Products!$C$2:$C$31,MATCH(E11,Products!$A$2:$A$31,0)),"Unknown") -> Books | H11: 45306 | I11: =IF(H11="","",MONTH(H11)) -> 1 | J11: =IF(H11="","",TEXT(H11,"mmm")) -> Jan | K11: =IF(H11="","","Q"&ROUNDUP(MONTH(H11)/3,0)) -> Q1 | L11: 7 | M11: 449.39 | N11: 0.15 | O11: =IFERROR(INDEX(Products!$D$2:$D$31,MATCH(E11,Products!$A$2:$A$31,0)),0) -> 345.35 | P11: =ROUND(L11*M11*(1-N11),2) -> 2673.87 | Q11: =ROUND(P11-L11*O11,2) -> 256.42 | R11: =IFERROR(Q11/P11,0) -> 0.095898454 | S11: =IF(L11>=5,"Bulk","Regular") -> Bulk | T11: =IF(R11>=0.3,"High",IF(R11>=0.15,"Medium","Low")) -> Low
A12: ORD1175 | B12: CUST010 | C12: =IFERROR(INDEX(Customers!$B$2:$B$31,MATCH(B12,Customers!$A$2:$A$31,0)),"Unknown") -> Imran Iyer | D12: =IFERROR(INDEX(Customers!$D$2:$D$31,MATCH(B12,Customers!$A$2:$A$31,0)),"Unknown") -> North | E12: PROD029 | F12: =IFERROR(INDEX(Products!$B$2:$B$31,MATCH(E12,Products!$A$2:$A$31,0)),"Unknown") -> Dumbbell Set | G12: =IFERROR(INDEX(Products!$C$2:$C$31,MATCH(E12,Products!$A$2:$A$31,0)),"Unknown") -> Sports | H12: 45306 | I12: =IF(H12="","",MONTH(H12)) -> 1 | J12: =IF(H12="","",TEXT(H12,"mmm")) -> Jan | K12: =IF(H12="","","Q"&ROUNDUP(MONTH(H12)/3,0)) -> Q1 | L12: 1 | M12: 1787.75 | N12: 0 | O12: =IFERROR(INDEX(Products!$D$2:$D$31,MATCH(E12,Products!$A$2:$A$31,0)),0) -> 1379.47 | P12: =ROUND(L12*M12*(1-N12),2) -> 1787.75 | Q12: =ROUND(P12-L12*O12,2) -> 408.28 | R12: =IFERROR(Q12/P12,0) -> 0.22837645 | S12: =IF(L12>=5,"Bulk","Regular") -> Regular | T12: =IF(R12>=0.3,"High",IF(R12>=0.15,"Medium","Low")) -> Medium
A13: ORD1204 | B13: CUST014 | C13: =IFERROR(INDEX(Customers!$B$2:$B$31,MATCH(B13,Customers!$A$2:$A$31,0)),"Unknown") -> Aisha Sharma | D13: =IFERROR(INDEX(Customers!$D$2:$D$31,MATCH(B13,Customers!$A$2:$A$31,0)),"Unknown") -> Central | E13: PROD009 | F13: =IFERROR(INDEX(Products!$B$2:$B$31,MATCH(E13,Products!$A$2:$A$31,0)),"Unknown") -> Hoodie | G13: =IFERROR(INDEX(Products!$C$2:$C$31,MATCH(E13,Products!$A$2:$A$31,0)),"Unknown") -> Apparel | H13: 45308 | I13: =IF(H13="","",MONTH(H13)) -> 1 | J13: =IF(H13="","",TEXT(H13,"mmm")) -> Jan | K13: =IF(H13="","","Q"&ROUNDUP(MONTH(H13)/3,0)) -> Q1 | L13: 6 | M13: 2810.89 | N13: 0.05 | O13: =IFERROR(INDEX(Products!$D$2:$D$31,MATCH(E13,Products!$A$2:$A$31,0)),0) -> 2252.73 | P13: =ROUND(L13*M13*(1-N13),2) -> 16022.07 | Q13: =ROUND(P13-L13*O13,2) -> 2505.69 | R13: =IFERROR(Q13/P13,0) -> 0.1563899 | S13: =IF(L13>=5,"Bulk","Regular") -> Bulk | T13: =IF(R13>=0.3,"High",IF(R13>=0.15,"Medium","Low")) -> Medium
A14: ORD1200 | B14: CUST005 | C14: =IFERROR(INDEX(Customers!$B$2:$B$31,MATCH(B14,Customers!$A$2:$A$31,0)),"Unknown") -> Aditya Khan | D14: =IFERROR(INDEX(Customers!$D$2:$D$31,MATCH(B14,Customers!$A$2:$A$31,0)),"Unknown") -> North | E14: PROD002 | F14: =IFERROR(INDEX(Products!$B$2:$B$31,MATCH(E14,Products!$A$2:$A$31,0)),"Unknown") -> Bluetooth Speaker | G14: =IFERROR(INDEX(Products!$C$2:$C$31,MATCH(E14,Products!$A$2:$A$31,0)),"Unknown") -> Electronics | H14: 45311 | I14: =IF(H14="","",MONTH(H14)) -> 1 | J14: =IF(H14="","",TEXT(H14,"mmm")) -> Jan | K14: =IF(H14="","","Q"&ROUNDUP(MONTH(H14)/3,0)) -> Q1 | L14: 5 | M14: 3664.93 | N14: 0 | O14: =IFERROR(INDEX(Products!$D$2:$D$31,MATCH(E14,Products!$A$2:$A$31,0)),0) -> 2293.21 | P14: =ROUND(L14*M14*(1-N14),2) -> 18324.65 | Q14: =ROUND(P14-L14*O14,2) -> 6858.6 | R14: =IFERROR(Q14/P14,0) -> 0.37428273 | S14: =IF(L14>=5,"Bulk","Regular") -> Bulk | T14: =IF(R14>=0.3,"High",IF(R14>=0.15,"Medium","Low")) -> High
... A257: ORD1221 | B257: CUST019 | C257: =IFERROR(INDEX(Customers!$B$2:$B$31,MATCH(B257,Customers!$A$2:$A$31,0)),"Unknown") -> Neha Khan | D257: =IFERROR(INDEX(Customers!$D$2:$D$31,MATCH(B257,Customers!$A$2:$A$31,0)),"Unknown") -> East | E257: PROD018 | F257: =IFERROR(INDEX(Products!$B$2:$B$31,MATCH(E257,Products!$A$2:$A$31,0)),"Unknown") -> Cook Book | G257: =IFERROR(INDEX(Products!$C$2:$C$31,MATCH(E257,Products!$A$2:$A$31,0)),"Unknown") -> Books | H257: 45656 | I257: =IF(H257="","",MONTH(H257)) -> 12 | J257: =IF(H257="","",TEXT(H257,"mmm")) -> Dec | K257: =IF(H257="","","Q"&ROUNDUP(MONTH(H257)/3,0)) -> Q4 | L257: 6 | M257: 2638.63 | N257: 0.1 | O257: =IFERROR(INDEX(Products!$D$2:$D$31,MATCH(E257,Products!$A$2:$A$31,0)),0) -> 1996.83 | P257: =ROUND(L257*M257*(1-N257),2) -> 14248.6 | Q257: =ROUND(P257-L257*O257,2) -> 2267.62 | R257: =IFERROR(Q257/P257,0) -> 0.15914686 | S257: =IF(L257>=5,"Bulk","Regular") -> Bulk | T257: =IF(R257>=0.3,"High",IF(R257>=0.15,"Medium","Low")) -> Medium
A258: ORD1225 | B258: CUST011 | C258: =IFERROR(INDEX(Customers!$B$2:$B$31,MATCH(B258,Customers!$A$2:$A$31,0)),"Unknown") -> Sai Khan | D258: =IFERROR(INDEX(Customers!$D$2:$D$31,MATCH(B258,Customers!$A$2:$A$31,0)),"Unknown") -> East | E258: PROD014 | F258: =IFERROR(INDEX(Products!$B$2:$B$31,MATCH(E258,Products!$A$2:$A$31,0)),"Unknown") -> LED Table Lamp | G258: =IFERROR(INDEX(Products!$C$2:$C$31,MATCH(E258,Products!$A$2:$A$31,0)),"Unknown") -> Home & Kitchen | I258: =IF(H258="","",MONTH(H258)) | J258: =IF(H258="","",TEXT(H258,"mmm")) | K258: =IF(H258="","","Q"&ROUNDUP(MONTH(H258)/3,0)) | L258: 5 | M258: 395.53 | N258: 0 | O258: =IFERROR(INDEX(Products!$D$2:$D$31,MATCH(E258,Products!$A$2:$A$31,0)),0) -> 300 | P258: =ROUND(L258*M258*(1-N258),2) -> 1977.65 | Q258: =ROUND(P258-L258*O258,2) -> 477.65 | R258: =IFERROR(Q258/P258,0) -> 0.24152403 | S258: =IF(L258>=5,"Bulk","Regular") -> Bulk | T258: =IF(R258>=0.3,"High",IF(R258>=0.15,"Medium","Low")) -> Medium
A259: ORD1032 | B259: CUST022 | C259: =IFERROR(INDEX(Customers!$B$2:$B$31,MATCH(B259,Customers!$A$2:$A$31,0)),"Unknown") -> Ayaan Kapoor | D259: =IFERROR(INDEX(Customers!$D$2:$D$31,MATCH(B259,Customers!$A$2:$A$31,0)),"Unknown") -> South | E259: PROD019 | F259: =IFERROR(INDEX(Products!$B$2:$B$31,MATCH(E259,Products!$A$2:$A$31,0)),"Unknown") -> Kids Story Book | G259: =IFERROR(INDEX(Products!$C$2:$C$31,MATCH(E259,Products!$A$2:$A$31,0)),"Unknown") -> Books | I259: =IF(H259="","",MONTH(H259)) | J259: =IF(H259="","",TEXT(H259,"mmm")) | K259: =IF(H259="","","Q"&ROUNDUP(MONTH(H259)/3,0)) | L259: 6 | M259: 1730.24 | N259: 0 | O259: =IFERROR(INDEX(Products!$D$2:$D$31,MATCH(E259,Products!$A$2:$A$31,0)),0) -> 1101.63 | P259: =ROUND(L259*M259*(1-N259),2) -> 10381.44 | Q259: =ROUND(P259-L259*O259,2) -> 3771.66 | R259: =IFERROR(Q259/P259,0) -> 0.36330798 | S259: =IF(L259>=5,"Bulk","Regular") -> Bulk | T259: =IF(R259>=0.3,"High",IF(R259>=0.15,"Medium","Low")) -> High
A260: ORD1165 | B260: CUST016 | C260: =IFERROR(INDEX(Customers!$B$2:$B$31,MATCH(B260,Customers!$A$2:$A$31,0)),"Unknown") -> Ira Singh | D260: =IFERROR(INDEX(Customers!$D$2:$D$31,MATCH(B260,Customers!$A$2:$A$31,0)),"Unknown") -> West | E260: PROD023 | F260: =IFERROR(INDEX(Products!$B$2:$B$31,MATCH(E260,Products!$A$2:$A$31,0)),"Unknown") -> Lipstick | G260: =IFERROR(INDEX(Products!$C$2:$C$31,MATCH(E260,Products!$A$2:$A$31,0)),"Unknown") -> Beauty | I260: =IF(H260="","",MONTH(H260)) | J260: =IF(H260="","",TEXT(H260,"mmm")) | K260: =IF(H260="","","Q"&ROUNDUP(MONTH(H260)/3,0)) | L260: 7 | M260: 2169.64 | N260: 0.2 | O260: =IFERROR(INDEX(Products!$D$2:$D$31,MATCH(E260,Products!$A$2:$A$31,0)),0) -> 1360.46 | P260: =ROUND(L260*M260*(1-N260),2) -> 12149.98 | Q260: =ROUND(P260-L260*O260,2) -> 2626.76 | R260: =IFERROR(Q260/P260,0) -> 0.21619459 | S260: =IF(L260>=5,"Bulk","Regular") -> Bulk | T260: =IF(R260>=0.3,"High",IF(R260>=0.15,"Medium","Low")) -> Medium
A261: ORD1047 | B261: CUST012 | C261: =IFERROR(INDEX(Customers!$B$2:$B$31,MATCH(B261,Customers!$A$2:$A$31,0)),"Unknown") -> Aditya Iyer | D261: =IFERROR(INDEX(Customers!$D$2:$D$31,MATCH(B261,Customers!$A$2:$A$31,0)),"Unknown") -> East | E261: PROD019 | F261: =IFERROR(INDEX(Products!$B$2:$B$31,MATCH(E261,Products!$A$2:$A$31,0)),"Unknown") -> Kids Story Book | G261: =IFERROR(INDEX(Products!$C$2:$C$31,MATCH(E261,Products!$A$2:$A$31,0)),"Unknown") -> Books | I261: =IF(H261="","",MONTH(H261)) | J261: =IF(H261="","",TEXT(H261,"mmm")) | K261: =IF(H261="","","Q"&ROUNDUP(MONTH(H261)/3,0)) | L261: 3 | M261: 1479.93 | N261: 0 | O261: =IFERROR(INDEX(Products!$D$2:$D$31,MATCH(E261,Products!$A$2:$A$31,0)),0) -> 1101.63 | P261: =ROUND(L261*M261*(1-N261),2) -> 4439.79 | Q261: =ROUND(P261-L261*O261,2) -> 1134.9 | R261: =IFERROR(Q261/P261,0) -> 0.2556202 | S261: =IF(L261>=5,"Bulk","Regular") -> Regular | T261: =IF(R261>=0.3,"High",IF(R261>=0.15,"Medium","Low")) -> Medium
A262: ORD1159 | B262: CUST017 | C262: =IFERROR(INDEX(Customers!$B$2:$B$31,MATCH(B262,Customers!$A$2:$A$31,0)),"Unknown") -> Kiara Khan | D262: =IFERROR(INDEX(Customers!$D$2:$D$31,MATCH(B262,Customers!$A$2:$A$31,0)),"Unknown") -> Central | E262: PROD024 | F262: =IFERROR(INDEX(Products!$B$2:$B$31,MATCH(E262,Products!$A$2:$A$31,0)),"Unknown") -> Hair Oil | G262: =IFERROR(INDEX(Products!$C$2:$C$31,MATCH(E262,Products!$A$2:$A$31,0)),"Unknown") -> Beauty | I262: =IF(H262="","",MONTH(H262)) | J262: =IF(H262="","",TEXT(H262,"mmm")) | K262: =IF(H262="","","Q"&ROUNDUP(MONTH(H262)/3,0)) | L262: 2 | M262: 3096.59 | N262: 0.2 | O262: =IFERROR(INDEX(Products!$D$2:$D$31,MATCH(E262,Products!$A$2:$A$31,0)),0) -> 2430.01 | P262: =ROUND(L262*M262*(1-N262),2) -> 4954.54 | Q262: =ROUND(P262-L262*O262,2) -> 94.52 | R262: =IFERROR(Q262/P262,0) -> 0.019077452 | S262: =IF(L262>=5,"Bulk","Regular") -> Regular | T262: =IF(R262>=0.3,"High",IF(R262>=0.15,"Medium","Low")) -> Low

Sheet Analysis
A1: SALES ANALYSIS
A2: Formula-driven summaries built with SUMIFS and COUNTIFS from Cleaned_Data.
A3: KEY PERFORMANCE INDICATORS
A4: Total Sales | C4: Total Profit | E4: Total Orders
A5: =SUM(Cleaned_Data!$P$3:$P$262) -> 1938477.7 | C5: =SUM(Cleaned_Data!$Q$3:$Q$262) -> 400069.4 | E5: =COUNTA(Cleaned_Data!$A$3:$A$262) -> 260
A6: Avg Order Value | C6: Overall Profit Margin % | E6: Avg Profit per Order
A7: =IFERROR(SUM(Cleaned_Data!$P$3:$P$262)/COUNTA(Cleaned_Data!$A$3:$A$262),0) -> 7455.6834 | C7: =IFERROR(SUM(Cleaned_Data!$Q$3:$Q$262)/SUM(Cleaned_Data!$P$3:$P$262),0) -> 0.20638329 | E7: =IFERROR(SUM(Cleaned_Data!$Q$3:$Q$262)/COUNTA(Cleaned_Data!$A$3:$A$262),0) -> 1538.7285
A9: REGION-WISE SUMMARY
A10: Region | B10: Total Sales | C10: Total Profit | D10: Order Count | E10: Avg Order Value
A11: North | B11: =SUMIFS(Cleaned_Data!$P$3:$P$262,Cleaned_Data!$D$3:$D$262,A11) -> 573120.01 | C11: =SUMIFS(Cleaned_Data!$Q$3:$Q$262,Cleaned_Data!$D$3:$D$262,A11) -> 116076.54 | D11: =COUNTIFS(Cleaned_Data!$D$3:$D$262,A11) -> 79 | E11: =IFERROR(B11/D11,0) -> 7254.6837
A12: Central | B12: =SUMIFS(Cleaned_Data!$P$3:$P$262,Cleaned_Data!$D$3:$D$262,A12) -> 542818.37 | C12: =SUMIFS(Cleaned_Data!$Q$3:$Q$262,Cleaned_Data!$D$3:$D$262,A12) -> 112813.36 | D12: =COUNTIFS(Cleaned_Data!$D$3:$D$262,A12) -> 65 | E12: =IFERROR(B12/D12,0) -> 8351.0518
A13: East | B13: =SUMIFS(Cleaned_Data!$P$3:$P$262,Cleaned_Data!$D$3:$D$262,A13) -> 364427.48 | C13: =SUMIFS(Cleaned_Data!$Q$3:$Q$262,Cleaned_Data!$D$3:$D$262,A13) -> 69530.69 | D13: =COUNTIFS(Cleaned_Data!$D$3:$D$262,A13) -> 55 | E13: =IFERROR(B13/D13,0) -> 6625.9542
A14: South | B14: =SUMIFS(Cleaned_Data!$P$3:$P$262,Cleaned_Data!$D$3:$D$262,A14) -> 233933.78 | C14: =SUMIFS(Cleaned_Data!$Q$3:$Q$262,Cleaned_Data!$D$3:$D$262,A14) -> 48855.38 | D14: =COUNTIFS(Cleaned_Data!$D$3:$D$262,A14) -> 36 | E14: =IFERROR(B14/D14,0) -> 6498.1606
A15: West | B15: =SUMIFS(Cleaned_Data!$P$3:$P$262,Cleaned_Data!$D$3:$D$262,A15) -> 224178.04 | C15: =SUMIFS(Cleaned_Data!$Q$3:$Q$262,Cleaned_Data!$D$3:$D$262,A15) -> 52793.43 | D15: =COUNTIFS(Cleaned_Data!$D$3:$D$262,A15) -> 25 | E15: =IFERROR(B15/D15,0) -> 8967.1216
A17: CATEGORY-WISE SUMMARY
A18: Category | B18: Total Sales | C18: Total Profit | D18: Order Count | E18: Avg Order Value
A19: Beauty | B19: =SUMIFS(Cleaned_Data!$P$3:$P$262,Cleaned_Data!$G$3:$G$262,A19) -> 497060.96 | C19: =SUMIFS(Cleaned_Data!$Q$3:$Q$262,Cleaned_Data!$G$3:$G$262,A19) -> 108135.09 | D19: =COUNTIFS(Cleaned_Data!$G$3:$G$262,A19) -> 47 | E19: =IFERROR(B19/D19,0) -> 10575.765
A20: Apparel | B20: =SUMIFS(Cleaned_Data!$P$3:$P$262,Cleaned_Data!$G$3:$G$262,A20) -> 398394.89 | C20: =SUMIFS(Cleaned_Data!$Q$3:$Q$262,Cleaned_Data!$G$3:$G$262,A20) -> 77656.18 | D20: =COUNTIFS(Cleaned_Data!$G$3:$G$262,A20) -> 48 | E20: =IFERROR(B20/D20,0) -> 8299.8935
A21: Electronics | B21: =SUMIFS(Cleaned_Data!$P$3:$P$262,Cleaned_Data!$G$3:$G$262,A21) -> 272764.95 | C21: =SUMIFS(Cleaned_Data!$Q$3:$Q$262,Cleaned_Data!$G$3:$G$262,A21) -> 59038.99 | D21: =COUNTIFS(Cleaned_Data!$G$3:$G$262,A21) -> 39 | E21: =IFERROR(B21/D21,0) -> 6993.9731
A22: Home & Kitchen | B22: =SUMIFS(Cleaned_Data!$P$3:$P$262,Cleaned_Data!$G$3:$G$262,A22) -> 259468.13 | C22: =SUMIFS(Cleaned_Data!$Q$3:$Q$262,Cleaned_Data!$G$3:$G$262,A22) -> 48903.84 | D22: =COUNTIFS(Cleaned_Data!$G$3:$G$262,A22) -> 44 | E22: =IFERROR(B22/D22,0) -> 5897.003
A23: Books | B23: =SUMIFS(Cleaned_Data!$P$3:$P$262,Cleaned_Data!$G$3:$G$262,A23) -> 259074.67 | C23: =SUMIFS(Cleaned_Data!$Q$3:$Q$262,Cleaned_Data!$G$3:$G$262,A23) -> 53492.05 | D23: =COUNTIFS(Cleaned_Data!$G$3:$G$262,A23) -> 41 | E23: =IFERROR(B23/D23,0) -> 6318.8944
A24: Sports | B24: =SUMIFS(Cleaned_Data!$P$3:$P$262,Cleaned_Data!$G$3:$G$262,A24) -> 251714.08 | C24: =SUMIFS(Cleaned_Data!$Q$3:$Q$262,Cleaned_Data!$G$3:$G$262,A24) -> 52843.25 | D24: =COUNTIFS(Cleaned_Data!$G$3:$G$262,A24) -> 41 | E24: =IFERROR(B24/D24,0) -> 6139.3678
A26: MONTHLY SUMMARY (2024)
A27: Month | B27: Total Sales | C27: Total Profit | D27: Order Count | E27: Avg Order Value
A28: Jan | B28: =SUMIFS(Cleaned_Data!$P$3:$P$262,Cleaned_Data!$I$3:$I$262,1) -> 167459.2 | C28: =SUMIFS(Cleaned_Data!$Q$3:$Q$262,Cleaned_Data!$I$3:$I$262,1) -> 41815.53 | D28: =COUNTIFS(Cleaned_Data!$I$3:$I$262,1) -> 19 | E28: =IFERROR(B28/D28,0) -> 8813.6421
A29: Feb | B29: =SUMIFS(Cleaned_Data!$P$3:$P$262,Cleaned_Data!$I$3:$I$262,2) -> 147091.14 | C29: =SUMIFS(Cleaned_Data!$Q$3:$Q$262,Cleaned_Data!$I$3:$I$262,2) -> 23692.25 | D29: =COUNTIFS(Cleaned_Data!$I$3:$I$262,2) -> 23 | E29: =IFERROR(B29/D29,0) -> 6395.267
A30: Mar | B30: =SUMIFS(Cleaned_Data!$P$3:$P$262,Cleaned_Data!$I$3:$I$262,3) -> 180483.79 | C30: =SUMIFS(Cleaned_Data!$Q$3:$Q$262,Cleaned_Data!$I$3:$I$262,3) -> 38632.93 | D30: =COUNTIFS(Cleaned_Data!$I$3:$I$262,3) -> 20 | E30: =IFERROR(B30/D30,0) -> 9024.1895
A31: Apr | B31: =SUMIFS(Cleaned_Data!$P$3:$P$262,Cleaned_Data!$I$3:$I$262,4) -> 102156.28 | C31: =SUMIFS(Cleaned_Data!$Q$3:$Q$262,Cleaned_Data!$I$3:$I$262,4) -> 16048.86 | D31: =COUNTIFS(Cleaned_Data!$I$3:$I$262,4) -> 14 | E31: =IFERROR(B31/D31,0) -> 7296.8771
A32: May | B32: =SUMIFS(Cleaned_Data!$P$3:$P$262,Cleaned_Data!$I$3:$I$262,5) -> 184220.43 | C32: =SUMIFS(Cleaned_Data!$Q$3:$Q$262,Cleaned_Data!$I$3:$I$262,5) -> 37231.63 | D32: =COUNTIFS(Cleaned_Data!$I$3:$I$262,5) -> 26 | E32: =IFERROR(B32/D32,0) -> 7085.4012
A33: Jun | B33: =SUMIFS(Cleaned_Data!$P$3:$P$262,Cleaned_Data!$I$3:$I$262,6) -> 176979.11 | C33: =SUMIFS(Cleaned_Data!$Q$3:$Q$262,Cleaned_Data!$I$3:$I$262,6) -> 38105.55 | D33: =COUNTIFS(Cleaned_Data!$I$3:$I$262,6) -> 22 | E33: =IFERROR(B33/D33,0) -> 8044.505
A34: Jul | B34: =SUMIFS(Cleaned_Data!$P$3:$P$262,Cleaned_Data!$I$3:$I$262,7) -> 128992.47 | C34: =SUMIFS(Cleaned_Data!$Q$3:$Q$262,Cleaned_Data!$I$3:$I$262,7) -> 30070.22 | D34: =COUNTIFS(Cleaned_Data!$I$3:$I$262,7) -> 22 | E34: =IFERROR(B34/D34,0) -> 5863.2941
A35: Aug | B35: =SUMIFS(Cleaned_Data!$P$3:$P$262,Cleaned_Data!$I$3:$I$262,8) -> 183602.88 | C35: =SUMIFS(Cleaned_Data!$Q$3:$Q$262,Cleaned_Data!$I$3:$I$262,8) -> 38698.37 | D35: =COUNTIFS(Cleaned_Data!$I$3:$I$262,8) -> 30 | E35: =IFERROR(B35/D35,0) -> 6120.096
A36: Sep | B36: =SUMIFS(Cleaned_Data!$P$3:$P$262,Cleaned_Data!$I$3:$I$262,9) -> 40913.2 | C36: =SUMIFS(Cleaned_Data!$Q$3:$Q$262,Cleaned_Data!$I$3:$I$262,9) -> 5229.17 | D36: =COUNTIFS(Cleaned_Data!$I$3:$I$262,9) -> 10 | E36: =IFERROR(B36/D36,0) -> 4091.32
A37: Oct | B37: =SUMIFS(Cleaned_Data!$P$3:$P$262,Cleaned_Data!$I$3:$I$262,10) -> 226156.72 | C37: =SUMIFS(Cleaned_Data!$Q$3:$Q$262,Cleaned_Data!$I$3:$I$262,10) -> 55063.27 | D37: =COUNTIFS(Cleaned_Data!$I$3:$I$262,10) -> 27 | E37: =IFERROR(B37/D37,0) -> 8376.1748
A38: Nov | B38: =SUMIFS(Cleaned_Data!$P$3:$P$262,Cleaned_Data!$I$3:$I$262,11) -> 159985.72 | C38: =SUMIFS(Cleaned_Data!$Q$3:$Q$262,Cleaned_Data!$I$3:$I$262,11) -> 27204.01 | D38: =COUNTIFS(Cleaned_Data!$I$3:$I$262,11) -> 19 | E38: =IFERROR(B38/D38,0) -> 8420.3011
A39: Dec | B39: =SUMIFS(Cleaned_Data!$P$3:$P$262,Cleaned_Data!$I$3:$I$262,12) -> 206533.34 | C39: =SUMIFS(Cleaned_Data!$Q$3:$Q$262,Cleaned_Data!$I$3:$I$262,12) -> 40172.12 | D39: =COUNTIFS(Cleaned_Data!$I$3:$I$262,12) -> 23 | E39: =IFERROR(B39/D39,0) -> 8979.7104
A40: QUARTERLY SUMMARY (2024)
A41: Quarter | B41: Total Sales | C41: Total Profit | D41: Order Count | E41: Avg Order Value
A42: Q1 | B42: =SUMIFS(Cleaned_Data!$P$3:$P$262,Cleaned_Data!$K$3:$K$262,A42) -> 495034.13 | C42: =SUMIFS(Cleaned_Data!$Q$3:$Q$262,Cleaned_Data!$K$3:$K$262,A42) -> 104140.71 | D42: =COUNTIFS(Cleaned_Data!$K$3:$K$262,A42) -> 62 | E42: =IFERROR(B42/D42,0) -> 7984.4215
A43: Q2 | B43: =SUMIFS(Cleaned_Data!$P$3:$P$262,Cleaned_Data!$K$3:$K$262,A43) -> 463355.82 | C43: =SUMIFS(Cleaned_Data!$Q$3:$Q$262,Cleaned_Data!$K$3:$K$262,A43) -> 91386.04 | D43: =COUNTIFS(Cleaned_Data!$K$3:$K$262,A43) -> 62 | E43: =IFERROR(B43/D43,0) -> 7473.481
...

Sheet Raw_Data
A1: RAW ORDER EXPORT — unprocessed (duplicates + missing values present)
A2: OrderID | B2: CustomerID | C2: ProductID | D2: OrderDate | E2: Quantity | F2: UnitPrice | G2: Discount
A3: ORD1079 | B3: CUST008 | C3: PROD027 | D3: 2024-11-22 | E3: 5 | F3: 2726.4 | G3: 0.1
A4: ORD1126 | B4: CUST004 | C4: PROD027 | D4: 2024-02-03 | E4: 7 | F4: 2501.43 | G4: 0.1
A5: ORD1221 | B5: CUST019 | C5: PROD018 | D5: 2024-12-30 | E5: 6 | F5: 2638.63 | G5: 0.1
A6: ORD1145 | B6: CUST019 | C6: PROD014 | D6: 2024-11-21 | E6: 8 | F6: 475.82 | G6: 0.05
A7: ORD1216 | B7: CUST015 | C7: PROD025 | D7: 2024-07-04 | E7: 2 | F7: 2927.53 | G7: 0
A8: ORD1016 | B8: CUST026 | C8: PROD014 | D8: 2024-04-07 | E8: 2 | F8: 358.09 | G8: 0.05
A9: ORD1139 | B9: CUST023 | C9: PROD010 | D9: 2024-12-24 | E9: 7 | F9: 1647.48 | G9: 0.1
A10: ORD1211 | B10: CUST011 | C10: PROD025 | D10: 45367 | E10: 1 | F10: 2757.45 | G10: 0
A11: ORD1049 | B11: CUST022 | C11: PROD004 | D11: 2024-06-30 | E11: 7 | F11: 1145.13 | G11: 0.15
A12: ORD1092 | B12: CUST011 | C12: PROD007 | D12: 2024-08-20 | E12: 6 | F12: 931.92 | G12: 0.05
A13: ORD1088 | B13: CUST014 | C13: PROD016 | D13: 2024-01-15 | E13: 7 | F13: 449.39 | G13: 0.15
A14: ORD1130 | B14: CUST015 | C14: PROD030 | D14: 2024-08-14 | E14: 5 | F14: 1115.49 | G14: 0.05
A15: ORD1143 | B15: CUST027 | C15: PROD009 | D15: 45587 | E15: 1 | F15: 3364.22 | G15: 0
A16: ORD1030 | B16: CUST028 | C16: PROD008 | D16: 2024-07-25 | E16: hb | F16: 2352.24
A17: ORD1235 | B17: CUST025 | C17: PROD010 | D17: 2024-06-22 | E17: 6 | F17: 1206.41 | G17: 0.2
A18: ORD1184 | B18: CUST019 | C18: PROD010 | D18: 2024-12-24 | E18: 5 | F18: 1213.86 | G18: 0.2
A19: ORD1120 | B19: CUST016 | C19: PROD009 | D19: 2024-10-28 | E19: 5 | F19: 3584.61 | G19: 0.2
A20: ORD1234 | B20: CUST027 | C20: PROD023 | D20: 2024-05-16 | E20: 1 | F20: 1674.98 | G20: 0.15
A21: ORD1069 | B21: CUST017 | C21: PROD022 | D21: 2024-11-20 | E21: 6 | F21: 2968.87 | G21: 0.2
A22: ORD1035 | B22: CUST030 | C22: PROD003 | D22: 2024-01-05 | E22: 8 | F22: 1701.73 | G22: 0.1
A23: ORD1084 | B23: CUST015 | C23: PROD014 | D23: 2024-02-01 | E23: 4 | F23: 457.44 | G23: 0.05
A24: ORD1195 | B24: CUST018 | C24: PROD012 | D24: 2024-02-16 | E24: 7 | F24: 2883.77 | G24: 0.1
A25: ORD1254 | B25: CUST011 | C25: PROD025 | D25: 2024-03-27 | E25: 2 | F25: 2984.45 | G25: 0
A26: ORD1123 | B26: CUST018 | C26: PROD010 | D26: 2024-12-23 | E26: 3 | F26: 1503.94 | G26: 0.2
A27: ORD1258 | B27: CUST003 | C27: PROD006 | D27: 2024-11-17 | E27: 8 | F27: 1954.62 | G27: 0.1
A28: ORD1015 | B28: CUST007 | C28: PROD018 | D28: 2024-03-08 | E28: 8 | F28: 2514.71 | G28: 0.05
... A34: ORD1181 | B34: CUST003 | C34: PROD015 | D34: 2024-06-25 | E34: 5 | F34: 278.91 | G34: 0.05
A35: ORD1156 | B35: CUST015 | C35: PROD004 | D35: 2024-11-27 | E35: 3 | F35: 990.86
A36: ORD1063 | B36: CUST024 | C36: PROD029 | D36: 2024-06-02 | E36: 5 | F36: 2000.37 | G36: 0
A37: ORD1218 | B37: CUST002 | C37: PROD016 | D37: 2024-07-24 | E37: 7 | F37: 503.78 | G37: 0.05
A38: ORD1076 | B38: CUST004 | C38: PROD015 | D38: 2024-03-09 | E38: 8 | F38: 281.41 | G38: 0.1
A39: ORD1260 | B39: CUST011 | C39: PROD005 | D39: 2024-08-13 | F39: 921.19 | G39: 0.15
A40: ORD1140 | B40: CUST018 | C40: PROD016 | D40: 2024-08-12 | E40: 2 | F40: 490.09 | G40: 0.05
A41: ORD1072 | B41: CUST003 | C41: PROD015 | D41: 2024-07-31 | E41: 4 | F41: 285.84 | G41: 0.05
A42: ORD1055 | B42: CUST028 | C42: PROD008 | D42: 2024-04-24 | E42: 1 | F42: 2162.85 | G42: 0.05
A43: ORD1034 | B43: CUST022 | C43: PROD021 | D43: 2024-06-02 | E43: 8 | F43: 1296.83 | G43: 0.2
A44: ORD1053 | B44: CUST023 | C44: PROD004 | D44: 2024-07-14 | E44: 1 | F44: 1107.74
A45: ORD1087 | B45: CUST025 | C45: PROD013 | D45: 2024-08-02 | E45: 4 | F45: 1798.49 | G45: 0
...

Sheet Cleaning_Log
A1: DATA CLEANING LOG
A2: Documents every cleaning step applied to Raw_Data to produce Cleaned_Data, and the assumption behind each fix.
A3: Step | B3: Records Affected | C3: Action | D3: Assumption / Rule Applied
A4: Raw rows loaded | B4: 280 | C4: Starting point | D4: Direct export from source system.
A5: Exact duplicate rows removed | B5: 14 | C5: Removed | D5: Fully identical rows are re-exports of the same order; safe to drop.
A6: Duplicate OrderID conflicts resolved | B6: 6 | C6: Retained with assumption | D6: Conflicting duplicate OrderID identified; first source occurrence retained as an explicit assumption because no reliable precedence field (timestamp/status/version) was available. See Exceptions_Log for the full list.
A7: Rows with missing OrderDate | B7: 5 | C7: Retained with assumption | D7: OrderDate can't be reliably guessed. These 5 valid orders are retained in Cleaned_Data with OrderDate/Month/Quarter left blank, so their Sales and Profit still count toward totals; they are simply excluded from monthly/quarterly trend views.
A8: Missing Quantity filled with dataset median (5) | B8: 4 | C8: Imputed | D8: Median is robust to outliers vs. mean; used as best estimate for a missing quantity.
A9: Missing UnitPrice filled with same-product median (fallback: overall median) | B9: 4 | C9: Imputed | D9: Same product usually sells near a consistent price; overall median used only if no other price exists for that product.
A10: Missing Discount filled with 0 (assumption: no discount recorded) | B10: 5 | C10: Imputed | D10: Blank discount is treated as 'no discount applied' rather than unknown.
A11: Final cleaned rows | B11: 260 | C11: Result | D11: Rows remaining in Cleaned_Data after all steps above (255 dated + 5 undated, valid orders).

Sheet Exceptions_Log
A1: EXCEPTIONS LOG — CONFLICTING DUPLICATE ORDER IDS
A2: Conflicting duplicate OrderIDs resolved by assuming the first entry as valid, pending verification.
A3: OrderID | B3: Issue | C3: Conflicting Values | D3: Action | E3: Reason
A4: ORD1180 | B4: Conflicting duplicate | C4: Quantity: 5 (first) vs 3 (second) | D4: First occurrence retained | E4: No reliable precedence field available
A5: ORD1021 | B5: Conflicting duplicate | C5: Quantity: 5 (first) vs 8 (second) | D5: First occurrence retained | E5: No reliable precedence field available
A6: ORD1039 | B6: Conflicting duplicate | C6: Quantity: 2 (first) vs 5 (second) | D6: First occurrence retained | E6: No reliable precedence field available
A7: ORD1157 | B7: Conflicting duplicate | C7: Quantity: 7 (first) vs 5 (second) | D7: First occurrence retained | E7: No reliable precedence field available
A8: ORD1090 | B8: Conflicting duplicate | C8: Quantity: 6 (first) vs 1 (second) | D8: First occurrence retained | E8: No reliable precedence field available
A9: ORD1249 | B9: Conflicting duplicate | C9: Quantity: 5 (first) vs 7 (second) | D9: First occurrence retained | E9: No reliable precedence field available

Sheet Customers
A1: CustomerID | B1: CustomerName | C1: City | D1: Region
A2: CUST001 | B2: Sana Singh | C2: Delhi | D2: North
A3: CUST002 | B3: Sai Kapoor | C3: Bengaluru | D3: South
A4: CUST003 | B4: Sana Chatterjee | C4: Lucknow | D4: North
A5: CUST004 | B5: Kiara Iyer | C5: Bhopal | D5: Central
A6: CUST005 | B6: Aditya Khan | C6: Delhi | D6: North
A7: CUST006 | B7: Navya Sharma | C7: Hyderabad | D7: South
A8: CUST007 | B8: Imran Mehta | C8: Bhopal | D8: Central
A9: CUST008 | B9: Kabir Patel | C9: Nagpur | D9: Central
A10: CUST009 | B10: Aisha Malhotra | C10: Nagpur | D10: Central
A11: CUST010 | B11: Imran Iyer | C11: Delhi | D11: North
A12: CUST011 | B12: Sai Khan | C12: Patna | D12: East
... A31: CUST030 | B31: Mohammed Patel | C31: Kolkata | D31: East

Sheet Products
A1: ProductID | B1: ProductName | C1: Category | D1: CostPrice
A2: PROD001 | B2: Wireless Earbuds | C2: Electronics | D2: 1037.43
A3: PROD002 | B3: Bluetooth Speaker | C3: Electronics | D3: 2293.21
A4: PROD003 | B4: Smartwatch | C4: Electronics | D4: 1190.42
A5: PROD004 | B5: Power Bank | C5: Electronics | D5: 721.01
A6: PROD005 | B6: USB-C Cable | C6: Electronics | D6: 676.84
A7: PROD006 | B7: Cotton T-Shirt | C7: Apparel | D7: 1438.51
A8: PROD007 | B8: Denim Jeans | C8: Apparel | D8: 715.83
A9: PROD008 | B9: Formal Shirt | C9: Apparel | D9: 1494.7
A10: PROD009 | B10: Hoodie | C10: Apparel | D10: 2252.73
A11: PROD010 | B11: Sports Shorts | C11: Apparel | D11: 1046.55
A12: PROD011 | B12: Non-Stick Pan | C12: Home & Kitchen | D12: 610.76
A13: PROD012 | B13: Electric Kettle | C13: Home & Kitchen | D13: 2494.04
... A31: PROD030 | B31: Skipping Rope | C31: Sports | D31: 725.72
